<?xml version="1.0"?>
<robot name="diff_drive_robot" xmlns:xacro="http://www.ros.org/wiki/xacro">

  <!-- ─────────────────────────────────────────
       PROPERTIES  (change these to match your
       real robot dimensions later)
  ───────────────────────────────────────────── -->
  <xacro:property name="chassis_mass"   value="5.0"/>
  <xacro:property name="chassis_l"      value="0.30"/>   <!-- length  x -->
  <xacro:property name="chassis_w"      value="0.25"/>   <!-- width   y -->
  <xacro:property name="chassis_h"      value="0.10"/>   <!-- height  z -->

  <xacro:property name="wheel_mass"     value="0.5"/>
  <xacro:property name="wheel_radius"   value="0.05"/>
  <xacro:property name="wheel_width"    value="0.04"/>

  <xacro:property name="caster_radius"  value="0.025"/>
  <xacro:property name="caster_mass"    value="0.1"/>

  <!-- wheel axle sits at chassis bottom + wheel_radius -->
  <xacro:property name="wheel_z_offset" value="-0.05"/>
  <xacro:property name="wheel_y_offset" value="0.145"/>

  <!-- ─────────────────────────────────────────
       INERTIA MACROS
       Box:      Ixx = m/12*(h²+d²)  etc.
       Cylinder: Ixx = Iyy = m/12*(3r²+h²)
                 Izz = m/2 * r²
  ───────────────────────────────────────────── -->
  <xacro:macro name="box_inertia" params="m l w h">
    <inertial>
      <mass value="${m}"/>
      <inertia
        ixx="${m/12*(w*w + h*h)}"  ixy="0" ixz="0"
        iyy="${m/12*(l*l + h*h)}"  iyz="0"
        izz="${m/12*(l*l + w*w)}"/>
    </inertial>
  </xacro:macro>

  <xacro:macro name="cylinder_inertia" params="m r h">
    <inertial>
      <mass value="${m}"/>
      <inertia
        ixx="${m/12*(3*r*r + h*h)}"  ixy="0" ixz="0"
        iyy="${m/12*(3*r*r + h*h)}"  iyz="0"
        izz="${m/2*r*r}"/>
    </inertial>
  </xacro:macro>

  <xacro:macro name="sphere_inertia" params="m r">
    <inertial>
      <mass value="${m}"/>
      <inertia
        ixx="${2/5*m*r*r}"  ixy="0" ixz="0"
        iyy="${2/5*m*r*r}"  iyz="0"
        izz="${2/5*m*r*r}"/>
    </inertial>
  </xacro:macro>

  <!-- ─────────────────────────────────────────
       BASE FOOTPRINT  (ground reference frame)
  ───────────────────────────────────────────── -->
  <link name="base_footprint"/>

  <joint name="base_footprint_joint" type="fixed">
    <parent link="base_footprint"/>
    <child  link="base_link"/>
    <origin xyz="0 0 ${wheel_radius}" rpy="0 0 0"/>
  </joint>

  <!-- ─────────────────────────────────────────
       CHASSIS
  ───────────────────────────────────────────── -->
  <link name="base_link">
    <visual>
      <geometry>
        <box size="${chassis_l} ${chassis_w} ${chassis_h}"/>
      </geometry>
      <material name="blue">
        <color rgba="0.2 0.4 0.8 1.0"/>
      </material>
    </visual>
    <collision>
      <geometry>
        <box size="${chassis_l} ${chassis_w} ${chassis_h}"/>
      </geometry>
    </collision>
    <xacro:box_inertia m="${chassis_mass}"
                       l="${chassis_l}"
                       w="${chassis_w}"
                       h="${chassis_h}"/>
  </link>

  <!-- ─────────────────────────────────────────
       WHEEL MACRO  (reused for left + right)
  ───────────────────────────────────────────── -->
  <xacro:macro name="wheel" params="name y_reflect">
    <link name="${name}_wheel">
      <visual>
        <geometry>
          <cylinder radius="${wheel_radius}" length="${wheel_width}"/>
        </geometry>
        <material name="black">
          <color rgba="0.1 0.1 0.1 1.0"/>
        </material>
      </visual>
      <collision>
        <geometry>
          <cylinder radius="${wheel_radius}" length="${wheel_width}"/>
        </geometry>
        <surface>
          <friction>
            <ode>
              <mu>1.5</mu>    <!-- static  friction μ₁ -->
              <mu2>1.5</mu2>  <!-- dynamic friction μ₂ -->
            </ode>
          </friction>
        </surface>
      </collision>
      <xacro:cylinder_inertia m="${wheel_mass}"
                               r="${wheel_radius}"
                               h="${wheel_width}"/>
    </link>

    <joint name="${name}_wheel_joint" type="continuous">
      <parent link="base_link"/>
      <child  link="${name}_wheel"/>
      <!-- rotate 90° so cylinder axis aligns with Y (axle direction) -->
      <origin xyz="0 ${y_reflect * wheel_y_offset} ${wheel_z_offset}"
              rpy="${pi/2} 0 0"/>
      <axis xyz="0 0 1"/>
      <dynamics damping="0.01" friction="0.01"/>
    </joint>
  </xacro:macro>

  <xacro:wheel name="left"  y_reflect=" 1"/>
  <xacro:wheel name="right" y_reflect="-1"/>

  <!-- ─────────────────────────────────────────
       CASTER WHEEL  (zero friction — pure pivot)
  ───────────────────────────────────────────── -->
  <link name="caster_wheel">
    <visual>
      <geometry>
        <sphere radius="${caster_radius}"/>
      </geometry>
      <material name="grey">
        <color rgba="0.6 0.6 0.6 1.0"/>
      </material>
    </visual>
    <collision>
      <geometry>
        <sphere radius="${caster_radius}"/>
      </geometry>
      <surface>
        <friction>
          <ode>
            <mu>0.0</mu>   <!-- μ₁ = 0 : mathematically pure pivot -->
            <mu2>0.0</mu2> <!-- μ₂ = 0 -->
          </ode>
        </friction>
      </surface>
    </collision>
    <xacro:sphere_inertia m="${caster_mass}" r="${caster_radius}"/>
  </link>

  <joint name="caster_joint" type="fixed">
    <parent link="base_link"/>
    <child  link="caster_wheel"/>
    <origin xyz="${-chassis_l/2 + caster_radius} 0 ${wheel_z_offset}"
            rpy="0 0 0"/>
  </joint>

  <!-- ─────────────────────────────────────────
       2D LiDAR
  ───────────────────────────────────────────── -->
  <link name="lidar_link">
    <visual>
      <geometry>
        <cylinder radius="0.04" length="0.04"/>
      </geometry>
      <material name="black">
        <color rgba="0.1 0.1 0.1 1.0"/>
      </material>
    </visual>
    <collision>
      <geometry>
        <cylinder radius="0.04" length="0.04"/>
      </geometry>

    </collision>
    <inertial>
      <mass value="0.1"/>
      <inertia ixx="0.0001" ixy="0" ixz="0"
               iyy="0.0001" iyz="0"
               izz="0.0001"/>
    </inertial>
  </link>

  <joint name="lidar_joint" type="fixed">
    <parent link="base_link"/>
    <child  link="lidar_link"/>
    <origin xyz="0 0 ${chassis_h/2 + 0.02}" rpy="0 0 0"/>
  </joint>

  <!-- ─────────────────────────────────────────
       RGB CAMERA
  ───────────────────────────────────────────── -->
  <link name="camera_link">
    <visual>
      <geometry>
        <box size="0.03 0.08 0.03"/>
      </geometry>
      <material name="red">
        <color rgba="0.8 0.1 0.1 1.0"/>
      </material>
    </visual>
    <collision>
      <geometry>
        <box size="0.03 0.08 0.03"/>
      </geometry>
    </collision>
    <inertial>
      <mass value="0.05"/>
      <inertia ixx="0.0001" ixy="0" ixz="0"
               iyy="0.0001" iyz="0"
               izz="0.0001"/>
    </inertial>
  </link>

  <joint name="camera_joint" type="fixed">
    <parent link="base_link"/>
    <child  link="camera_link"/>
    <origin xyz="${chassis_l/2} 0 ${chassis_h/4}" rpy="0 0 0"/>
  </joint>

  <!-- Camera optical frame (ROS convention: Z forward, X right, Y down) -->
  <link name="camera_optical_link"/>
  <joint name="camera_optical_joint" type="fixed">
    <parent link="camera_link"/>
    <child  link="camera_optical_link"/>
    <origin xyz="0 0 0" rpy="${-pi/2} 0 ${-pi/2}"/>
  </joint>
  
  <!-- ─────────────────────────────────────────
       GAZEBO PLUGINS
  ───────────────────────────────────────────── -->

  <!-- Differential drive controller -->
  <gazebo>
    <plugin filename="gz-sim-diff-drive-system"
            name="gz::sim::systems::DiffDrive">
      <left_joint>left_wheel_joint</left_joint>
      <right_joint>right_wheel_joint</right_joint>
      <wheel_separation>0.29</wheel_separation>
      <wheel_radius>0.05</wheel_radius>
      <odom_publish_frequency>50</odom_publish_frequency>
      <topic>cmd_vel</topic>
      <odom_topic>odom</odom_topic>
      <frame_id>odom</frame_id>
      <child_frame_id>base_footprint</child_frame_id>
    </plugin>
  </gazebo>

  <!-- 2D LiDAR -->
  <gazebo reference="lidar_link">
    <sensor name="lidar" type="gpu_lidar">
      <topic>scan</topic>
      <update_rate>10</update_rate>
      <lidar>
        <scan>
          <horizontal>
            <samples>360</samples>
            <resolution>1</resolution>
            <min_angle>-3.14159</min_angle>
            <max_angle>3.14159</max_angle>
          </horizontal>
        </scan>
        <range>
          <min>0.12</min>
          <max>10.0</max>
          <resolution>0.01</resolution>
        </range>
      </lidar>
      <always_on>1</always_on>
      <visualize>true</visualize>
    </sensor>
  </gazebo>

  <!-- RGB Camera -->
  <gazebo reference="camera_link">
    <sensor name="camera" type="camera">
      <topic>camera/image</topic>
      <update_rate>30</update_rate>
      <camera>
        <horizontal_fov>1.047</horizontal_fov>
        <image>
          <width>640</width>
          <height>480</height>
          <format>R8G8B8</format>
        </image>
        <clip>
          <near>0.1</near>
          <far>100</far>
        </clip>
      </camera>
      <always_on>1</always_on>
      <visualize>true</visualize>
    </sensor>
  </gazebo>
</robot>

